Workbook

Sheet Detailed Requirements
A1: Sequence as per user Flow | B1: High Level FR | C1: FR | D1: Screen | E1: CTA Button | F1: Task # | G1: Task Details | H1: Description / Scope | I1: Acceptance Criteria | J1: Task Type | K1: Dependent On | L1: Effort (w/o AI) | M1: Effort (w/ AI) | N1: Effort w/ AI + Buffer (days) | O1: AI Stack | P1: Standard Stack | Q1: DB Operation | R1: Store | S1: Tables / Measurements | T1: Key fields written / read | U1: API Contract | V1: Handoff Output → Next FR
A2: 1 | B2: Uploading requirements | C2: FR-001 | D2: Design & Author | E2: Drop file or click | F2: BE-01 | G2: Defines and stores the allowed file formats (PDF, DOCX, XLSX, CSV) as a centralised whitelist configurable via environment variables without code redeployment. | H2: • Defines the allowed file formats (PDF, DOCX, XLSX, CSV) as a centralized whitelist stored in a config/enum. • Configuration is injectable via environment variables without requiring code deployment. • MIME types and file extensions are stored together for validation purposes. | I2: • Must return exactly 4 entries: application/pdf, .docx, .xlsx, text/csv • Must allow adding a new type via environment variable configuration • Must apply configuration changes without requiring code redeployment • Must store MIME types and file extensions together in the whitelist | J2: Backend Dev | L2: 2 | M2: 0.5 | N2: =MAX(ROUND(M2*1.2/0.25,0)*0.25,0.25) -> 0.5 | O2: GitHub Copilot — generate enum + YAML config boilerplate Claude — design MIME whitelist logic & edge cases | P2: Spring Boot · Java Enum · AWS SSM Parameter Store · Spring @ConfigurationProperties | Q2: WRITE (session) | R2: Redis (session only) | S2: session.checkpoint_data [in-memory pool] | T2: No test_case / test_step write. File bytes + parsed TCs held in session only. Pool is client-side state. | U2: INTERNAL CONFIG: Whitelist constant — no HTTP endpoint. Config: application.yml allowed-mime-types: - application/pdf - application/vnd.openxmlformats-officedocument .wordprocessingml.document - application/vnd.openxmlformats-officedocument .spreadsheetml.sheet - text/csv Used by: FR-001 BE-10 (Upload API) for validation.
A3: 1 | B3: Uploading requirements | C3: FR-001 | D3: Design & Author | E3: Drop file or click | F3: BE-02 | G3: Enforces a configurable maximum file size limit (default 20 MB) at tenant level, rejecting uploads that exceed the threshold before any processing begins. | H3: • Enforces a configurable maximum file size limit (default 20 MB) at tenant level, stored in the tenant_config table. • Platform enforces a hard cap (e.g. 200 MB) via AWS SSM that tenants cannot exceed. • Tenant admins adjust their limit through Settings → General, and the value is read at runtime per tenant without restart. • Uploads exceeding the threshold are rejected before any processing begins. | I3: • Must default to 20 MB for all new tenants on provisioning • Must allow tenant admin to update the limit via Settings → General up to the platform hard cap • Must apply the updated limit on the next upload attempt without service restart • Must reject values of 0, negative numbers, or values above the platform hard cap with a clear error • Must never allow tenant-configured limits to exceed the platform hard cap enforced via AWS SSM | J3: Backend Dev | K3: FR-001 BE-01 · Settings → General (tenant_config write) | L3: 2 | M3: 0.5 | N3: =MAX(ROUND(M3*1.2/0.25,0)*0.25,0.25) -> 0.5 | O3: GitHub Copilot — scaffold @ConfigurationProperties class + unit tests | P3: Spring Boot · application.yml · AWS SSM Parameter Store · Spring @ConfigurationProperties | Q3: WRITE (session) | R3: Redis (session only) | S3: session.checkpoint_data [in-memory pool] | T3: No test_case / test_step write. File bytes + parsed TCs held in session only. Pool is client-side state. | U3: INTERNAL CONFIG: No HTTP endpoint. Config: application.yml max-upload-size-mb: 20 Runtime-injectable via env var ICE_MAX_UPLOAD_MB. Used by: FR-001 BE-10 (Upload API) for size check.
A4: 1 | B4: Uploading requirements | C4: FR-001 | D4: Design & Author | E4: Drop file or click | F4: BE-03 | G4: Maintains a registry of structured error codes and human-readable messages for all upload rejection scenarios, ensuring consistent error responses across clients. | H4: • Maintains a registry of structured error codes for all upload rejection scenarios (ERR-001-FORMAT, ERR-001-SIZE, ERR-001-CORRUPT, ERR-001-EMPTY, ERR-002-FORMAT, ERR-002-SIZE). • Each error code has a corresponding human-readable message string stored as a Java enum. • Registry is referenced by BE-04, BE-05, BE-06, and all tests to ensure consistent error responses. | I4: • Must contain all 6 error codes with corresponding message strings: ERR-001-FORMAT, ERR-001-SIZE, ERR-001-CORRUPT, ERR-001-EMPTY, ERR-002-FORMAT, ERR-002-SIZE • Must map each error code to exactly one failure scenario with no ambiguity • Must allow adding a new error code via enum update only, requiring no other code changes • Must document all error codes in OpenAPI spec with message and HTTP status | J4: Backend Dev | L4: 1 | M4: 0.25 | N4: =MAX(ROUND(M4*1.2/0.25,0)*0.25,0.25) -> 0.25 | O4: GitHub Copilot — generate error code enum + exception handler Claude — define error taxonomy & priority order | P4: Java Enum · OpenAPI / Swagger annotations · Spring Boot | Q4: WRITE (session) | R4: Redis (session only) | S4: session.checkpoint_data [in-memory pool] | T4: No test_case / test_step write. File bytes + parsed TCs held in session only. Pool is client-side state. | U4: INTERNAL — Error code enum, no HTTP endpoint. Codes returned inside Upload API response body: ERR-001-FORMAT — wrong file type ERR-001-SIZE — exceeds max size ERR-001-CORRUPT — unreadable file ERR-001-EMPTY — zero-byte file Response shape: {code, message, detail}
A5: 1 | B5: Uploading requirements | C5: FR-001 | D5: Design & Author | E5: Drop file or click | F5: BE-04 | G5: Validates the MIME type of each uploaded file against the whitelist, rejecting files whose declared type does not match the allowed set. | H5: • Validates the MIME type of each uploaded file against the whitelist using Apache Tika for server-side enforcement. • Reads actual file bytes to detect real content type, not browser-reported File.type or file extension. • Whitelist configuration is read from FR-001 BE-01 at runtime. • Files whose declared type does not match the allowed set are rejected. | I5: • Must validate MIME type using Apache Tika by reading actual file bytes, not browser-reported File.type or file extension • Must reject .exe file renamed to .pdf after Tika detects application/x-msdownload with ERR-002-FORMAT • Must accept valid PDF files that match whitelist • Must return ERR-002-FORMAT on rejection • Must read whitelist configuration from FR-001 BE-01, applying new types without code change | J5: Backend Dev | K5: FR-001 / BE-01 | L5: 2 | M5: 0.5 | N5: =MAX(ROUND(M5*1.2/0.25,0)*0.25,0.25) -> 0.5 | O5: GitHub Copilot — generate Tika integration + whitelist check Claude — edge case logic for polyglot files | P5: Apache Tika · Spring Boot · Java Enum (whitelist) | Q5: READ (session) | R5: Redis (session only) | S5: [in-memory upload context] | T5: Reads uploaded file bytes from session context. Returns validation result. No DB write on pass. On fail: error code returned to FE; session cleared. | U5: INTERNAL — called inside FR-001 BE-10 handler. Apache Tika validates actual bytes (not extension). Returns: {valid, detected_mime, error_code} Errors emitted: ERR-001-FORMAT, ERR-001-CORRUPT Not a standalone HTTP endpoint. This is the security gate — client check (FR-001 FE-01) is UX only and does not replace this.
A6: 1 | B6: Uploading requirements | C6: FR-001 | D6: Design & Author | E6: Drop file or click | F6: BE-05 | G6: Enforces the file size limit at the API layer before the file reaches storage, returning a structured error if the limit is exceeded. | H6: • Enforces the file size limit at the API layer by validating actual received bytes, not Content-Length header. • Reads the configurable max size limit from FR-001 BE-02 (AWS SSM / application.yml) at runtime. • Rejects files exceeding the limit before any parsing occurs. • Returns a structured error if the limit is exceeded. | I6: • Must validate actual received byte count, not Content-Length header • Must reject files exceeding the configured limit with HTTP 413 + ERR-002-SIZE • Must read the configurable max size limit from FR-001 BE-02 at runtime • Must apply configuration changes from FR-001 BE-02 without service restart • Must reject files even when Content-Length header is spoofed to bypass validation | J6: Backend Dev | K6: FR-001 / BE-02 | L6: 2 | M6: 0.5 | N6: =MAX(ROUND(M6*1.2/0.25,0)*0.25,0.25) -> 0.5 | O6: GitHub Copilot — scaffold size enforcement + config binding | P6: Spring Boot · AWS SSM · @ConfigurationProperties | Q6: READ (session) | R6: Redis (session only) | S6: [in-memory upload context] | T6: Reads uploaded file bytes from session context. Returns validation result. No DB write on pass. On fail: error code returned to FE; session cleared. | U6: INTERNAL — called inside FR-001 BE-10 handler. Compares file size against configured max. Config: ICE_MAX_UPLOAD_MB (default 20). Emits: ERR-001-SIZE if exceeded. Not a standalone HTTP endpoint.
A7: 1 | B7: Uploading requirements | C7: FR-001 | D7: Design & Author | E7: Drop file or click | F7: BE-06 | G7: Defines the standard JSON error response schema returned on upload failure, including error code, message, and resolution hint fields. | H7: • Defines the standard JSON error response schema with fields: code, message, and detail. • Implements Spring Boot @ControllerAdvice that catches validation failures and serializes them using the error code registry from FR-001 BE-03. • Applies priority order for error reporting: format → size → integrity. | I7: • Must return all validation failures as JSON with fields: code, message, and detail • Must never return raw 500 errors or plain text responses • Must use error codes that match FR-001 BE-03 registry exactly • Must return the first failure in priority order when multiple simultaneous failures occur: format → size → integrity | J7: Backend Dev | K7: FR-001 / BE-03 | L7: 1 | M7: 0.25 | N7: =MAX(ROUND(M7*1.2/0.25,0)*0.25,0.25) -> 0.25 | O7: GitHub Copilot — generate error schema + @ControllerAdvice Claude — error priority order design | P7: Spring Boot @ControllerAdvice · OpenAPI 3.0 · Java Enum | Q7: READ (session) | R7: Redis (session only) | S7: [in-memory upload context] | T7: Reads uploaded file bytes from session context. Returns validation result. No DB write on pass. On fail: error code returned to FE; session cleared. | U7: INTERNAL — defines error response schema. All validation errors returned as: HTTP 400 {code: 'ERR-001-*', message: string, detail: string} No raw 500s. No generic 'upload failed' string.
A8: 1 | B8: Uploading requirements | C8: FR-001 | D8: Design & Author | E8: Drop file or click | F8: BE-07 | G8: Validates file integrity by checking for corruption or truncation after upload, ensuring the received file matches the declared content length. | H8: • Validates file integrity by attempting to parse the file using format-specific libraries (pdfplumber, python-docx, openpyxl, csv.reader). • Performs deep integrity check after upload to ensure the received file matches declared content length. • Rejects files that are corrupt, zero-byte, truncated, or password-protected. | I8: • Must return ERR-001-CORRUPT for corrupt .pdf files • Must return ERR-001-CORRUPT for password-protected DOCX files • Must return ERR-001-EMPTY for zero-byte files • Must accept valid parseable files of all 4 types: PDF, DOCX, XLSX, CSV • Must validate file integrity by parsing with format-specific libraries: pdfplumber, python-docx, openpyxl, csv.reader | J8: Backend Dev | K8: FR-001 / BE-01, BE-10 | L8: 4 | M8: 1 | N8: =MAX(ROUND(M8*1.2/0.25,0)*0.25,0.25) -> 1.25 | O8: GitHub Copilot — generate per-format parser stubs Claude — edge case logic (password-protected, zero-byte) | P8: pdfplumber · python-docx · openpyxl · csv.reader · Spring Boot | Q8: WRITE (session) | R8: Redis (session only) | S8: session.checkpoint_data [in-memory pool] | T8: No test_case / test_step write. File bytes + parsed TCs held in session only. Pool is client-side state. | U8: INTERNAL — called inside BE-10 upload handler. Runs Apache Tika on file bytes to verify real MIME type matches declared extension. Returns: {valid: bool, detected_mime, error_code} Not a standalone HTTP endpoint.
A9: 1 | B9: Uploading requirements | C9: FR-001 | D9: Design & Author | E9: Drop file or click | F9: BE-08 | G9: Stores the uploaded file reference in the active session context so downstream CLAP steps can access it without re-upload. | H9: • Stores the uploaded file reference in the active session context keyed by session ID. • Uploaded file bytes and parsed content are held in active session only, with no write to ICE DB. • Downstream CLAP steps access the file from session context without re-upload. | I9: • Must store uploaded file reference in active session context keyed by session ID • Must allow file content to be retrievable within same session by session ID • Must return null for expired session IDs • Must write zero rows to any ICE DB table during Step 1 • Must hold uploaded file bytes and parsed content in active session only with no write to ICE DB | J9: Backend Dev | L9: 4 | M9: 1.5 | N9: =MAX(ROUND(M9*1.2/0.25,0)*0.25,0.25) -> 1.75 | O9: GitHub Copilot — generate Redis session config + unit tests Claude — session isolation design | P9: Spring Session · Redis · Spring Security · Jackson (serialisation) | Q9: WRITE (session) | R9: Redis (session only) | S9: session.checkpoint_data [in-memory pool] | T9: No test_case / test_step write. File bytes + parsed TCs held in session only. Pool is client-side state. | U9: INTERNAL — Session store, no HTTP endpoint. Redis key: ice:session:{session_id}:upload Stores: {file_bytes, parsed_content, file_name, mime_type, size_bytes} TTL: matches session expires_at (4 ). Read by: FR-003 BE-07 (Gateway Orchestrator)
A10: 1 | B10: Uploading requirements | C10: FR-001 | D10: Design & Author | E10: Drop file or click | F10: BE-09 | G10: Supports multiple file uploads per session, allowing users to add further requirement documents without restarting the session. | H10: • Supports multiple file uploads per session, allowing users to add further requirement documents without restarting. • Each uploaded file is stored with a unique sessionFileId within the session context. • All files are held in session and passed to CLAP for test case generation. | I10: • Must allow multiple files to be uploaded in the same session • Must store each uploaded file with a unique sessionFileId within the session context • Must keep each sessionFileId independently resolvable within the session • Must enable the Generate button after at least one valid file is uploaded • Must update the file list in UI to show all uploaded files • Must allow removing individual files without affecting others or ending the session | J10: Backend Dev | K10: FR-001 / BE-08, BE-10 | L10: 2 | M10: 0.5 | N10: =MAX(ROUND(M10*1.2/0.25,0)*0.25,0.25) -> 0.5 | O10: GitHub Copilot — generate session replacement logic + concurrent tests | P10: Spring Session · Redis TTL / key eviction · JUnit 5 | Q10: WRITE (session) | R10: Redis (session only) | S10: session.checkpoint_data [in-memory pool] | T10: No test_case / test_step write. File bytes + parsed TCs held in session only. Pool is client-side state. | U10: INTERNAL — session guard called inside BE-10. Checks Redis for existing upload in session. If found: returns 409 with message 'Session already has a file. Remove it first.' Not a standalone HTTP endpoint.
A11: 1 | B11: Uploading requirements | C11: FR-001 | D11: Design & Author | E11: Drop file or click | F11: BE-10 | G11: Exposes the POST /api/v1/upload endpoint that accepts multipart file uploads, validates them, and returns a file reference on success. | H11: • Exposes POST /api/v1/sessions/{session_id}/upload endpoint that accepts multipart/form-data. • Orchestrates the validation pipeline: MIME check (BE-04) → size check (BE-05) → integrity check (BE-07) → session store (BE-08). • Returns a file reference on success or structured error response using codes from BE-03 registry. | I11: • Must return HTTP 200 + { sessionFileId, fileName, sizeBytes, format } for valid file uploads • Must return HTTP 422 + ERR-001-FORMAT for invalid file format • Must return HTTP 413 + ERR-001-SIZE for oversized files • Must return HTTP 422 + ERR-001-CORRUPT for corrupt files • Must return HTTP 422 + ERR-001-EMPTY for empty files • Must reject requests containing more than one file per request • Must orchestrate validation pipeline: MIME check (BE-04) → size check (BE-05) → integrity check (BE-07) → session store (BE-08) | J11: Backend Dev | K11: FR-001 / BE-03, BE-04, BE-05, BE-07, BE-08 | L11: 4 | M11: 1.5 | N11: =MAX(ROUND(M11*1.2/0.25,0)*0.25,0.25) -> 1.75 | O11: GitHub Copilot — generate MultipartFile controller + validation chain Claude — API contract design Postman AI — generate test collection from OpenAPI spec | P11: Spring Boot · Spring MVC (MultipartFile) · OpenAPI 3.0 · JUnit 5 + Mockito | Q11: WRITE (session) | R11: Redis (session only) | S11: session.checkpoint_data [in-memory pool] | T11: No test_case / test_step write. File bytes + parsed TCs held in session only. Pool is client-side state. | U11: ENDPOINT YOU CREATE: POST /api/v1/sessions/{session_id}/upload Content-Type: multipart/form-data Body: file (binary) Response 200: {file_name, size_bytes, mime_type, session_id, uploaded_at} Errors: 400 ERR-001-FORMAT — invalid mime type 400 ERR-001-SIZE — exceeds limit 400 ERR-001-CORRUPT — unreadable 400 ERR-001-EMPTY — zero bytes 409 — session already has a file | V11: → FR-002 BE-02 session.uploadedFiles[sessionFileId] = { fileBytes, parsedText, format, fileName, sizeBytes } FR-002 BE-02 reads parsedText from this key.
A12: 1 | B12: Uploading requirements | C12: FR-001 | D12: Design & Author | E12: Drop file or click | F12: FE-01 | G12: Renders the file upload area on the Design & Author screen, supporting both drag-and-drop and click-to-browse file selection. | H12: • Renders the file upload area on the Design & Author screen supporting both drag-and-drop and click-to-browse file selection. • Single file upload only with multi-file disabled. • Accepts the 4 allowed extensions at OS picker level. | I12: • Must restrict file picker accept attribute to .pdf,.docx,.xlsx,.csv • Must accept single file via drag-and-drop • Must reject multiple files dropped simultaneously • Must show placeholder/prompt when no file is loaded • Must support both drag-and-drop and click-to-browse file selection | J12: Frontend Dev | L12: 4 | M12: 1 | N12: =MAX(ROUND(M12*1.2/0.25,0)*0.25,0.25) -> 1.25 | O12: v0.dev — generate drag-and-drop upload UI component GitHub Copilot — react-dropzone wiring + validation logic | P12: React · react-dropzone · TypeScript · Tailwind CSS · HTML5 File API | Q12: WRITE (session) | R12: Redis (session only) | S12: session.checkpoint_data [in-memory pool] | T12: No test_case / test_step write. File bytes + parsed TCs held in session only. Pool is client-side state. | U12: ENDPOINT YOU CALL (defined in FR-001 BE-10): POST /api/v1/sessions/{session_id}/upload Send: multipart/form-data with file field. On 200: show file name + size, enable Generate. On 400 ERR-001-FORMAT: show format error inline. On 400 ERR-001-SIZE: show size error inline. On 409: prompt user to remove existing file first. While uploading: show progress indicator (FE-03).
A13: 1 | B13: Uploading requirements | C13: FR-001 | D13: Design & Author | E13: Drop file or click | F13: FE-02 | G13: Displays inline validation error messages directly below the upload area when a file is rejected, using the error codes from BE-03. | H13: • Displays inline validation error messages directly below the upload area when a file is rejected. • Shows error code and human-readable message from BE-03 registry. • Uses inline banner only, no modal or toast notification. | I13: • Must display error message within 300 ms of rejection • Must show error code and plain-English description from BE-03 registry • Must clear error when user selects a new file • Must use inline banner only, not modal or toast notification • Must display error directly below the upload area | J13: Frontend Dev | L13: 2 | M13: 0.5 | N13: =MAX(ROUND(M13*1.2/0.25,0)*0.25,0.25) -> 0.5 | O13: v0.dev — generate inline error banner component GitHub Copilot — error code ↔ message mapping | P13: React · Tailwind CSS · TypeScript | Q13: WRITE (session) | R13: Redis (session only) | S13: session.checkpoint_data [in-memory pool] | T13: No test_case / test_step write. File bytes + parsed TCs held in session only. Pool is client-side state. | U13: No API call — pure UI component. Listens for error state from FE-01 (FE-04) and renders inline error banner below upload zone. Displays: error code + human-readable message. Clears on new file selection.
A14: 1 | B14: Uploading requirements | C14: FR-001 | D14: Design & Author | E14: Drop file or click | F14: FE-03 | G14: Shows a progress indicator during upload, reflecting real-time upload percentage and transitioning to a success state on completion. | H14: • Shows a progress indicator (spinner or bar) during file transmission and validation. • Upload area is locked and non-interactive during in-progress state. • Transitions to success state on completion. | I14: • Must display a progress indicator (spinner or bar) immediately upon file selection or drop • Must lock the upload area and make it non-interactive during the upload process • Must transition the indicator to a success state upon successful upload completion • Must remove the indicator on error and allow the upload area to become interactive again | J14: Frontend Dev | L14: 2 | M14: 0.5 | N14: =MAX(ROUND(M14*1.2/0.25,0)*0.25,0.25) -> 0.5 | O14: v0.dev — generate progress indicator UI GitHub Copilot — Axios interceptor for progress events | P14: React · Tailwind CSS · Axios · HTML5 upload progress event | Q14: WRITE (session) | R14: Redis (session only) | S14: session.checkpoint_data [in-memory pool] | T14: No test_case / test_step write. File bytes + parsed TCs held in session only. Pool is client-side state. | U14: No API call — pure UI component. Reads XMLHttpRequest upload progress event from FE-04 API integration call. Shows % progress bar while upload is in flight.
A15: 1 | B15: Uploading requirements | C15: FR-001 | D15: Design & Author | E15: Drop file or click | F15: FE-04 | G15: Calls the BE-10 upload API on file selection, handles the response, and passes the file reference to the session context. | H15: • Calls POST /api/v1/upload (BE-10) when file is selected in the upload UI (FE-01). • On success, stores sessionFileId in application state for session context. • On failure, passes error code to error display component (FE-02). | I15: • Must trigger exactly one POST request to /api/v1/upload when a file is selected in FE-01 • Must store sessionFileId in application state and display the file name when HTTP 200 is received • Must surface the specific error code inline when HTTP 422 or 413 is received • Must display a user-friendly retry message on network timeout • Must pass the error code to the error display component (FE-02) on any failure response | J15: Frontend Dev | K15: FR-001 / FE-01, FE-02, FE-03, BE-10 | L15: 3 | M15: 1 | N15: =MAX(ROUND(M15*1.2/0.25,0)*0.25,0.25) -> 1.25 | O15: GitHub Copilot — Axios call + React Query wiring Cursor — auto-wire error codes to FE-02 display | P15: React · Axios · React Query / Redux Toolkit · TypeScript · Jest + React Testing Library | Q15: WRITE (session) | R15: Redis (session only) | S15: session.checkpoint_data [in-memory pool] | T15: No test_case / test_step write. File bytes + parsed TCs held in session only. Pool is client-side state. | U15: ENDPOINT YOU CALL (defined in FR-001 BE-10): POST /api/v1/sessions/{session_id}/upload Wire file from FE-01 dropzone to this endpoint. Use XMLHttpRequest (not fetch) for progress events. Headers: Content-Type: multipart/form-data On success: notify FE-01, FE-05, FE-06. On error: pass error code to FE-02 for display.
A16: 1 | B16: Uploading requirements | C16: FR-001 | D16: Design & Author | E16: Drop file or click | F16: FE-05 | G16: Enables the Generate & Add to Pool button only after at least one valid file has been successfully uploaded and its reference stored in session. | H16: • Generate Test Cases button is disabled until a valid file is confirmed with sessionFileId in state. • Button is enabled only after at least one valid file has been successfully uploaded. • Re-disables if file is cleared or replaced before new upload completes. | I16: • Must keep the Generate Test Cases button disabled on page load • Must enable the button only after HTTP 200 response sets sessionFileId in state • Must disable the button again if the file is cleared before a new upload completes • Must set aria-disabled='true' attribute in the disabled state, not rely on visual styling alone | J16: Frontend Dev | K16: FR-001 / FE-04 | L16: 2 | M16: 0.5 | N16: =MAX(ROUND(M16*1.2/0.25,0)*0.25,0.25) -> 0.5 | O16: GitHub Copilot — button state logic + aria-disabled wiring Cursor — generate enable/disable state machine | P16: React · TypeScript · ARIA attributes · Jest + Testing Library | Q16: WRITE (session) | R16: Redis (session only) | S16: session.checkpoint_data [in-memory pool] | T16: No test_case / test_step write. File bytes + parsed TCs held in session only. Pool is client-side state. | U16: ENDPOINT YOU CALL (defined in FR-001 BE-10): Watch response from POST /upload. Enable Generate button only when 200 received and session has a file (check via GET /api/v1/sessions/{id}/status). Disable if session file removed or expired.
A17: 1 | B17: Uploading requirements | C17: FR-001 | D17: Design & Author | E17: Drop file or click | F17: FE-06 | G17: Displays the uploaded file name and metadata (size, type) alongside the upload area as confirmation of a successful upload. | H17: • Displays the uploaded file name, format badge, and file size after successful upload as confirmation to the user. • The file metadata is rendered alongside the upload area in the frontend UI. • Provides Remove and Replace affordances to clear the file and reset the upload state. | I17: • Must display the uploaded file name accurately, truncating with a tooltip if longer than 40 characters • Must show a format badge displaying one of: PDF, DOCX, XLSX, or CSV • Must display file size in KB or MB rounded to 1 decimal place • Must clear sessionFileId and disable the Generate button when the Remove action is clicked • Must provide both Remove and Replace affordances alongside the file metadata display | J17: Frontend Dev | K17: FR-001 / FE-04 | L17: 2 | M17: 0.5 | N17: =MAX(ROUND(M17*1.2/0.25,0)*0.25,0.25) -> 0.5 | O17: v0.dev — generate file metadata card UI GitHub Copilot — truncation + tooltip + Remove handler | P17: React · TypeScript · Tailwind CSS · React Tooltip · Bytes.js | Q17: WRITE (session) | R17: Redis (session only) | S17: session.checkpoint_data [in-memory pool] | T17: No test_case / test_step write. File bytes + parsed TCs held in session only. Pool is client-side state. | U17: ENDPOINT YOU CALL (defined in FR-001 BE-10): Read {file_name, size_bytes} from POST /upload 200 response to display file metadata strip below upload zone (name · size · type badge).
A18: 1 | B18: Uploading requirements | C18: FR-001 | D18: Design & Author | E18: Drop file or click | F18: INT-01 | G18: Validates the full upload happy path: valid file selected, uploaded successfully, file reference stored in session, Generate button enabled. | H18: • Validates the complete upload happy path for all 4 supported file formats from file selection through to Generate button enablement. • Tests that upload succeeds, file name is displayed, Generate button is enabled, and sessionFileId is scoped to the session only. • Covers the full end-to-end flow ensuring file reference is stored in session and ready for generation. | I18: • Must complete the full upload flow without error for each of the 4 supported file formats (PDF, DOCX, XLSX, CSV) • Must display the file name and enable the Generate button after each successful upload • Must ensure that two parallel browser sessions each see only their own uploaded file • Must not create any DB rows in ICE tables during the upload process | J18: QA / Both Devs | K18: FR-001 / All BE + FE tasks | L18: 3 | M18: 1 | N18: =MAX(ROUND(M18*1.2/0.25,0)*0.25,0.25) -> 1.25 | O18: Playwright AI — generate E2E test scripts from user stories Claude — generate test scenarios from AC GitHub Actions AI — suggest CI pipeline config | P18: Playwright · Cypress · Docker Compose · GitHub Actions CI | Q18: WRITE (session) | R18: Redis (session only) | S18: session.checkpoint_data [in-memory pool] | T18: No test_case / test_step write. File bytes + parsed TCs held in session only. Pool is client-side state. | U18: ENDPOINT UNDER TEST: POST /api/v1/sessions/{session_id}/upload Test cases: 200 — valid PDF, DOCX, XLSX, CSV 400 ERR-001-FORMAT — .exe file 400 ERR-001-SIZE — 25MB file 400 ERR-001-CORRUPT — corrupted PDF 400 ERR-001-EMPTY — empty file 409 — second upload same session
A19: 1 | B19: Uploading requirements | C19: FR-001 | D19: Design & Author | E19: Drop file or click | F19: INT-02 | G19: Validates all upload rejection paths including wrong format, oversized file, corrupted file, and duplicate upload within the same session. | H19: • Validates all upload rejection scenarios including wrong format, oversized file, corrupted file, and duplicate upload within the same session. • Tests both client-side fast-fail validation (FE-01) and server-side enforcement (BE-04, BE-05, BE-07). • Verifies that each error code surfaces correctly in the UI inline banner with the appropriate message. | I19: • Must reject files with wrong extensions client-side with ERR-001-FORMAT in under 100ms • Must reject .exe files renamed to .pdf with ERR-002-FORMAT via Tika server-side validation (BE-04) • Must reject polyglot files with ERR-002-FORMAT as ambiguous • Must reject files larger than 20 MB with ERR-001-SIZE client-side and ERR-002-SIZE server-side (BE-05) • Must reject corrupted files with ERR-001-CORRUPT (BE-07) • Must reject zero-byte files with an appropriate error code | J19: QA / Both Devs | K19: FR-001 / BE-07, BE-04, BE-05, BE-06, FE-01, FE-02, INT-01 | L19: 3 | M19: 1 | N19: =MAX(ROUND(M19*1.2/0.25,0)*0.25,0.25) -> 1.25 | O19: Playwright AI — generate negative test scripts for all ERR-001-* codes Postman AI — generate error scenario collection Claude — generate edge case matrix | P19: Playwright · Cypress · Postman / REST Assured · JUnit 5 · GitHub Actions CI | Q19: WRITE (session) | R19: Redis (session only) | S19: session.checkpoint_data [in-memory pool] | T19: No test_case / test_step write. File bytes + parsed TCs held in session only. Pool is client-side state. | U19: ENDPOINT UNDER TEST: POST /api/v1/sessions/{session_id}/upload Focus: all error scenarios. Verify: each error code returned correctly, FE displays correct inline message per code, no raw 500s surface to UI.
A20: 2 | B20: Extract the requirement ,structure & loading to CLAP session | C20: FR-002 | D20: Design & Author | E20: Drop file or click | F20: BE-01 | G20: Builds the structured prompt template that wraps the extracted requirement content before it is sent to CLAP, ensuring consistent formatting across all generation requests. | H20: • Builds the structured prompt template that wraps extracted requirement content before sending to CLAP. • Loads and renders admin-configurable templates stored in the system configuration. • Injects template variables including {requirements}, {format}, and {examples} to ensure consistent formatting across all generation requests. | I20: • Must render the prompt template with all 3 required variables: {requirements}, {format}, and {examples} • Must load admin-configurable templates from system configuration without requiring a restart • Must raise a clear configuration error at startup if any template variable is undefined | J20: Backend Dev | L20: 3 | M20: 0.75 | N20: =MAX(ROUND(M20*1.2/0.25,0)*0.25,0.25) -> 1 | O20: GitHub Copilot — generate template engine + variable resolver Claude — template variable validation design | P20: Mustache / Thymeleaf · Spring Boot · AWS SSM | Q20: READ (session) | R20: Redis (session only) | S20: session.checkpoint_data [in-memory file context] | T20: Reads: requirements context from session. Builds structured CLAP prompt. No DB write — internal step in the generation pipeline. | U20: INTERNAL — prompt template engine. Builds structured CLAP prompt from: requirements context + BDD spec + config. Template stored in: /resources/prompts/ tc_generation.mustache Not a standalone HTTP endpoint. Called by: FR-003 BE-07 (Gateway Orchestrator).
A21: 2 | B21: Extract the requirement ,structure & loading to CLAP session | C21: FR-002 | D21: Design & Author | E21: Drop file or click | F21: BE-02 | G21: Constructs the BDD output format specification that CLAP uses as its target structure when generating test cases (Feature / Scenario / Given / When / Then). | H21: • Constructs the BDD output format specification that CLAP uses as its target structure when generating test cases. • Builds the {format} variable containing the Gherkin field specification including Feature, Scenario, Given, When, Then, and And. • Ensures the LLM receives a clear schema definition to guide structured test case generation. | I21: • Must include the format specification in every generated prompt • Must match the 9-field Gherkin schema defined in FR-004 (Feature, Scenario, Given, When, Then, And) • Must version the format specification alongside the schema | J21: Backend Dev | K21: FR-002 / BE-01 | L21: 2 | M21: 0.5 | N21: =MAX(ROUND(M21*1.2/0.25,0)*0.25,0.25) -> 0.5 | O21: GitHub Copilot — generate format spec builder from schema | P21: Spring Boot · Java Constants / Enum | Q21: READ (session) | R21: Redis (session only) | S21: session.checkpoint_data [in-memory file context] | T21: Reads: requirements context from session. Builds structured CLAP prompt. No DB write — internal step in the generation pipeline. | U21: INTERNAL — BDD format spec builder. Appends BDD format instructions to prompt: Given/When/Then structure, field names, output JSON schema. Not a standalone HTTP endpoint.
A22: 2 | B22: Extract the requirement ,structure & loading to CLAP session | C22: FR-002 | D22: Design & Author | E22: Drop file or click | F22: BE-03 | G22: Extracts and injects the requirement document content into the session context, making it available to CLAP for test case generation. | H22: • Extracts requirement document content and injects it into the session context for CLAP to use during test case generation. • The uploaded requirements content is inserted into the {requirements} prompt variable. • Truncates content gracefully to stay within the model token limit while preserving requirement integrity. | I22: • Must inject the full requirement document content into the {requirements} variable if within token limit • Must gracefully truncate content using the most relevant sections when the token limit is exceeded • Must log all truncation events for audit purposes | J22: Backend Dev | K22: FR-002 / BE-01 | L22: 4 | M22: 1 | N22: =MAX(ROUND(M22*1.2/0.25,0)*0.25,0.25) -> 1.25 | O22: GitHub Copilot — generate context injector + truncation logic Claude — truncation strategy design | P22: Spring AI (token counting) · Apache Commons Text · Spring Boot | Q22: READ (session) | R22: Redis (session only) | S22: session.checkpoint_data [in-memory file context] | T22: Reads: requirements context from session. Builds structured CLAP prompt. No DB write — internal step in the generation pipeline. | U22: INTERNAL — requirements context injector. Reads parsed file content from session Redis key ice:session:{id}:upload Injects into prompt template. Not a standalone HTTP endpoint.
A23: 2 | B23: Extract the requirement ,structure & loading to CLAP session | C23: FR-002 | D23: Design & Author | E23: Drop file or click | F23: BE-04 | G23: Logs every prompt sent to CLAP including the session ID, timestamp, and token count, providing an audit trail for traceability and debugging. | H23: • Logs every prompt sent to CLAP including sessionId, timestamp, templateVersion, and tokenCount for audit and traceability. • Sensitive information such as secrets is excluded from the logged prompt content. • Provides a complete audit trail for debugging and compliance purposes. | I23: • Must log every prompt sent to CLAP with 4 required fields: sessionId, timestamp, templateVersion, and tokenCount • Must exclude all sensitive information including api_key and PII from logged prompt content • Must make all prompt logs queryable by sessionId | J23: Backend Dev | K23: FR-002 / BE-01,BE-03,BE-02 | L23: 2 | M23: 0.5 | N23: =MAX(ROUND(M23*1.2/0.25,0)*0.25,0.25) -> 0.5 | O23: GitHub Copilot — generate audit logger + PII redactor | P23: Spring Boot · Logback / SLF4J · Elasticsearch / CloudWatch | Q23: READ (session) | R23: Redis (session only) | S23: session.checkpoint_data [in-memory file context] | T23: Reads: requirements context from session. Builds structured CLAP prompt. No DB write — internal step in the generation pipeline. | U23: ENDPOINT YOU CREATE: GET /api/v1/sessions/{session_id}/prompt-log Response 200: {session_id, prompt_version, prompt_hash, template_used, injected_at, token_count} Admin/debug use only. 403 for non-admin users. Used by: FR-004 INT-01 for audit verification. | V23: → FR-003 BE-06 session.builtPrompt[sessionId] = { promptText, tokenCount, templateVersion, requirementsHash, formatSpec } FR-003 BE-06 reads promptText and dispatches to LLM.
A24: 2 | B24: Extract the requirement ,structure & loading to CLAP session | C24: FR-002 | D24: Design & Author | E24: Drop file or click | F24: INT-01 | G24: Validates the full prompt construction pipeline: file uploaded, content extracted, prompt built, and CLAP receives well-formed input with correct BDD spec. | H24: • Validates the full prompt construction pipeline from file upload through content extraction to final prompt delivery to CLAP. • Verifies the prompt contains all 3 required variables: {requirements}, {format}, and {examples}. • Confirms the well-formed prompt with correct BDD format specification is successfully sent to the LLM gateway. | I24: • Must validate that the constructed prompt includes all 3 required variables: {requirements}, {format}, and {examples} • Must ensure the final prompt token count is within the model's token limit • Must create an audit log entry for each prompt generation event | J24: QA / Both Devs | K24: FR-002 / All BE | L24: 3 | M24: 0.75 | N24: =MAX(ROUND(M24*1.2/0.25,0)*0.25,0.25) -> 1 | O24: Playwright AI — generate E2E prompt validation tests Claude — generate audit log verification scenarios | P24: Playwright · WireMock · GitHub Actions CI | Q24: READ (session) | R24: Redis (session only) | S24: session.checkpoint_data [in-memory file context] | T24: Reads: requirements context from session. Builds structured CLAP prompt. No DB write — internal step in the generation pipeline. | U24: ENDPOINT UNDER TEST: GET /api/v1/sessions/{session_id}/prompt-log Test: after generate call, verify prompt log populated with correct template + token count. Test: requirements context present in log.
A25: 3 | B25: ICE sends prompt to CLAP | C25: FR-003 | D25: Design & Author | E25: Generate & Add to Pool | F25: BE-01 | G25: Defines the LLM provider configuration schema including provider name, model, API key, and temperature, stored per tenant in the ICE database. | H25: • Defines the LLM provider configuration schema including provider name, model, api_key_ref, and timeout parameters. • Stored per tenant in the ICE database with API keys referenced from secret manager. • The runtime configuration is retrieved and applied when constructing LLM API requests. | I25: • Must load the LLM provider configuration with 4 required fields: provider name, model, api_key_ref, and timeout • Must resolve api_key from the secret manager and never log it in plain text • Must raise a clear configuration error on startup if the provider name is invalid | J25: Backend Dev | L25: 3 | M25: 1 | N25: =MAX(ROUND(M25*1.2/0.25,0)*0.25,0.25) -> 1.25 | O25: GitHub Copilot — generate config schema + secret resolver Claude — secret manager integration design | P25: Spring Boot · AWS SSM / Secrets Manager · application.yml | Q25: WRITE (session) | R25: Redis (session only) | S25: session.checkpoint_data [in-memory pool] | T25: Reads: session file context. Calls CLAP (Claude API). Writes generated TC list to in-memory pool. No test_case write. | U25: INTERNAL CONFIG — LLM provider settings. Stored in: tenant.llm_config JSONB Fields: provider (claude|gpt4o|gemini), model_version, max_tokens, temperature Exposed via FR-003 BE-06 Config Admin API.
A26: 3 | B26: ICE sends prompt to CLAP | C26: FR-003 | D26: Design & Author | E26: Generate & Add to Pool | F26: BE-02 | G26: Resolves the active LLM provider for the current tenant and constructs the provider-specific API request before sending to CLAP. | H26: • Resolves the active LLM provider configuration for the current tenant and constructs provider-specific API requests. • Retrieves the api_key_ref from AWS Secrets Manager at runtime when making CLAP calls. • Auto-refreshes API keys within 60 seconds of rotation in the secret manager. | I26: • Must resolve the active LLM provider configuration for the current tenant from tenant settings • Must retrieve the api_key_ref from AWS Secrets Manager at runtime when making CLAP calls • Must reflect API key rotation within 60 seconds of change without service restart • Must never log or persist API keys in logs or database tables • Must return a provider-specific API request payload ready for transmission | J26: Backend Dev | L26: 4 | M26: 1.5 | N26: =MAX(ROUND(M26*1.2/0.25,0)*0.25,0.25) -> 1.75 | O26: GitHub Copilot — generate Secrets Manager client + cache Claude — rotation/TTL design | P26: AWS Secrets Manager / HashiCorp Vault · Spring Boot · Caffeine Cache | Q26: WRITE (session) | R26: Redis (session only) | S26: session.checkpoint_data [in-memory pool] | T26: Reads: session file context. Calls CLAP (Claude API). Writes generated TC list to in-memory pool. No test_case write. | U26: INTERNAL — Secret Manager integration. API keys stored encrypted in AWS SSM or Vault. Retrieved at runtime via SecretManagerService. Never stored in DB plain-text. Not an HTTP endpoint. Called by: FR-003 BE-07 Gateway Orchestrator.
A27: 3 | B27: ICE sends prompt to CLAP | C27: FR-003 | D27: Design & Author | E27: Generate & Add to Pool | F27: BE-03 | G27: Manages the streaming connection between ICE and the CLAP LLM, handling token streaming, timeouts, and connection errors. | H27: • Manages the streaming connection between ICE and the CLAP LLM including token streaming, timeouts, and connection errors. • Defines the ChatClient interface via Spring AI as the abstraction layer for all LLM provider calls. • All provider interactions are routed through this unified interface for consistency. | I27: • Must support streaming connections with GPT-4o, Claude, and Gemini adapters via the ChatClient interface • Must allow provider swap via configuration change without code modification • Must normalize all provider responses to a standard schema regardless of source provider • Must handle token streaming, connection timeouts, and connection errors during the LLM call • Must surface connection errors with clear error codes when the stream is interrupted or fails | J27: Backend Dev | L27: 4 | M27: 1.5 | N27: =MAX(ROUND(M27*1.2/0.25,0)*0.25,0.25) -> 1.75 | O27: GitHub Copilot — generate adapter stubs for each provider Claude — interface contract design | P27: Spring AI · ChatClient · Java Interface · Spring Boot | Q27: WRITE (session) | R27: Redis (session only) | S27: session.checkpoint_data [in-memory pool] | T27: Reads: session file context. Calls CLAP (Claude API). Writes generated TC list to in-memory pool. No test_case write. | U27: INTERNAL — ILLMProvider adapter interface. Interface: {generate(prompt): LLMResponse} Implementations: ClaudeProvider, GPT4oProvider, GeminiProvider. Selected at runtime based on tenant.llm_config. Not an HTTP endpoint.
A28: 3 | B28: ICE sends prompt to CLAP | C28: FR-003 | D28: Design & Author | E28: Generate & Add to Pool | F28: BE-04 | G28: Implements retry logic for transient CLAP API failures, with configurable back-off and a maximum retry count before surfacing an error to the user. | H28: • Implements retry logic for transient CLAP API failures with configurable back-off and maximum retry count. • Defines error codes ERR-003-TIMEOUT, ERR-003-RATE_LIMIT, ERR-003-PROVIDER_ERROR, and ERR-003-EMPTY_RESPONSE for specific failure scenarios. • Surfaces a clear error to the user after exhausting all retry attempts. | I28: • Must retry transient CLAP API failures using configurable exponential back-off • Must enforce a maximum retry count before surfacing failure to the caller • Must return ERR-003-TIMEOUT for timeout failures, ERR-003-RATE_LIMIT for rate limit errors, ERR-003-PROVIDER_ERROR for provider failures, and ERR-003-EMPTY_RESPONSE for empty responses • Must structure all errors as { code, message, detail } without exposing raw LLM error messages to the UI • Must log each retry attempt with error code and retry count for diagnostics | J28: Backend Dev | L28: 2 | M28: 0.5 | N28: =MAX(ROUND(M28*1.2/0.25,0)*0.25,0.25) -> 0.5 | O28: GitHub Copilot — generate error registry + exception handler Claude — error taxonomy design | P28: Spring Boot @ControllerAdvice · Java Enum · OpenAPI 3.0 | Q28: WRITE (session) | R28: Redis (session only) | S28: session.checkpoint_data [in-memory pool] | T28: Reads: session file context. Calls CLAP (Claude API). Writes generated TC list to in-memory pool. No test_case write. | U28: INTERNAL — error code registry for LLM failures. Codes: ERR-003-TIMEOUT, ERR-003-PROVIDER_DOWN, ERR-003-TOKEN_LIMIT, ERR-003-INVALID_RESPONSE Returned inside Generate API response body.
A29: 3 | B29: ICE sends prompt to CLAP | C29: FR-003 | D29: Design & Author | E29: Generate & Add to Pool | F29: BE-05 | G29: Enforces token limits per request to prevent runaway generation costs, truncating the prompt context if necessary while preserving requirement fidelity. | H29: • Enforces token limits per request to prevent runaway generation costs and manage LLM usage. • Normalizes prompts to a standard schema before sending to the LLM using admin-configurable templates. • Truncates prompt context if necessary while preserving requirement fidelity and staying within token budget. | I29: • Must enforce a per-request token limit to prevent runaway generation costs • Must build prompts from requirements + BDD format spec + admin-configurable template • Must allow template changes via configuration without requiring deployment • Must truncate prompt context if necessary while preserving essential requirement data • Must log the final prompt (excluding secrets) for audit purposes | J29: Backend Dev | K29: FR-003 / BE-01 | L29: 5 | M29: 1.5 | N29: =MAX(ROUND(M29*1.2/0.25,0)*0.25,0.25) -> 1.75 | O29: GitHub Copilot — generate prompt builder + template engine Claude — template variable validation | P29: Spring AI · Mustache / Thymeleaf · Spring Boot | Q29: WRITE (session) | R29: Redis (session only) | S29: session.checkpoint_data [in-memory pool] | T29: Reads: session file context. Calls CLAP (Claude API). Writes generated TC list to in-memory pool. No test_case write. | U29: INTERNAL — prompt normalisation layer. Strips PII, truncates to token limit, adds BDD format spec header. Called by: FR-002 BE-02 Requirements Context Injector before sending to CLAP. Not an HTTP endpoint.
A30: 3 | B30: ICE sends prompt to CLAP | C30: FR-003 | D30: Design & Author | E30: Generate & Add to Pool | F30: BE-06 | G30: Tracks CLAP API usage metrics per tenant (tokens consumed, latency, error rate) for billing and performance monitoring. | H30: • Tracks CLAP API usage metrics per tenant including tokens consumed, latency, and error rate for billing and performance monitoring. • Exposes a REST endpoint for admins to read and update LLM provider configuration at runtime. • Configuration changes take effect immediately without requiring system restart. | I30: • Must track tokens consumed, latency, and error rate per tenant for billing and performance monitoring • Must expose GET endpoint that returns current provider and model without exposing the API key • Must allow admin PATCH to update provider configuration and apply changes on the next CLAP call • Must return HTTP 403 for non-admin users attempting to read or update LLM configuration • Must apply configuration changes without service restart | J30: Backend Dev | K30: FR-003 / BE-01,BE-02 | L30: 3 | M30: 1 | N30: =MAX(ROUND(M30*1.2/0.25,0)*0.25,0.25) -> 1.25 | O30: GitHub Copilot — generate admin REST controller + auth guard | P30: Spring Boot · Spring Security · OpenAPI 3.0 | Q30: WRITE (session) | R30: Redis (session only) | S30: session.checkpoint_data [in-memory pool] | T30: Reads: session file context. Calls CLAP (Claude API). Writes generated TC list to in-memory pool. No test_case write. | U30: ENDPOINT YOU CREATE: GET /api/v1/admin/llm-config PUT /api/v1/admin/llm-config Request (PUT): {provider, model_version, max_tokens, temperature} Response 200: {provider, model_version, status: active|fallback} Errors: 400 invalid provider, 403 not admin
A31: 3 | B31: ICE sends prompt to CLAP | C31: FR-003 | D31: Design & Author | E31: Generate & Add to Pool | F31: BE-07 | G31: Validates the CLAP API key and provider connectivity at session start, surfacing a clear error before the user attempts generation. | H31: • Validates the CLAP API key and provider connectivity at session start before the user attempts generation. • Exposes the /health/llm endpoint to check LLM provider health status. • Automatically falls back to the secondary provider if the primary provider is unhealthy. | I31: • Must validate CLAP API key and provider connectivity at session start before generation is attempted • Must expose /health/llm endpoint returning { provider, status, latencyMs } • Must automatically fall back to the secondary provider if the primary provider is unhealthy • Must log fallback events with timestamp, primary provider status, and secondary provider used • Must surface a clear error message if both primary and secondary providers are unavailable | J31: Backend Dev | K31: FR-003 / BE-08 | L31: 4 | M31: 1.5 | N31: =MAX(ROUND(M31*1.2/0.25,0)*0.25,0.25) -> 1.75 | O31: GitHub Copilot — generate health check + fallback logic | P31: Spring Boot Actuator · Spring AI · Micrometer | Q31: WRITE (session) | R31: Redis (session only) | S31: session.checkpoint_data [in-memory pool] | T31: Reads: session file context. Calls CLAP (Claude API). Writes generated TC list to in-memory pool. No test_case write. | U31: INTERNAL — health check + provider fallback. GET /api/v1/internal/llm/health (internal only) Response: {provider, status: ok|degraded|down} On primary provider down: falls back to secondary provider if configured.
A32: 3 | B32: ICE sends prompt to CLAP | C32: FR-003 | D32: Design & Author | E32: Generate & Add to Pool | F32: BE-08 | G32: Caches repeated identical prompts within a session to avoid redundant CLAP calls when the user regenerates without changing the requirements. | H32: • Caches identical prompts within a session to avoid redundant CLAP calls when users regenerate without changing requirements. • Orchestrates the workflow by receiving the prompt, routing to the provider, receiving the response, normalizing it, and returning the result. • Retries failed requests up to 3 times before surfacing an error. | I32: • Must cache identical prompts within a session to avoid redundant CLAP calls on regeneration without requirement changes • Must orchestrate the workflow by receiving the prompt, routing to the provider, normalizing the response, and returning it • Must return a normalized response containing content, tokenUsage, modelUsed, and latencyMs for valid prompts • Must retry provider timeouts up to 3 times before returning ERR-003-TIMEOUT • Must return cached response immediately if the prompt matches a prior request in the same session | J32: Backend Dev | K32: FR-002 / BE-04 FR-003 / BE-01, FR-014 BE-01, FR-014 BE-02, FR-015 BE-01, BE-05 | L32: 3 | M32: 1 | N32: =MAX(ROUND(M32*1.2/0.25,0)*0.25,0.25) -> 1.25 | O32: GitHub Copilot — generate orchestrator + retry logic Claude — partial response detection | P32: Spring AI · Spring Retry · Jackson · Spring Boot | Q32: WRITE (session) | R32: Redis (session only) | S32: session.checkpoint_data [in-memory pool] | T32: Reads: session file context. Calls CLAP (Claude API). Writes generated TC list to in-memory pool. No test_case write. | U32: INTERNAL — Gateway Orchestrator. Coordinates: prompt build → provider call → response parse → validate → return. Called by FR-004 BE-04 Generation API Endpoint. Not a standalone HTTP endpoint. | V32: → FR-004 BE-02 LlmResponse = { content (raw JSON string), tokenUsage, modelUsed, latencyMs } FR-004 BE-02 parses content into 9-field TC objects.
A33: 3 | B33: ICE sends prompt to CLAP | C33: FR-003 | D33: Design & Author | E33: Generate & Add to Pool | F33: FE-01 | G33: Renders the Generate & Add to Pool button and manages its enabled/loading/disabled states throughout the generation lifecycle. | H33: • Renders the Generate & Add to Pool button and manages its enabled, loading, and disabled states throughout the generation lifecycle. • Displays the active LLM provider and health badge in the UI header. • Polls the /health/llm endpoint every 30 seconds to update provider status. | I33: • Must display a badge showing the active LLM provider name and green/red health status in the UI header • Must poll the /health/llm endpoint every 30 seconds to refresh the provider health status • Must update the badge within 30 seconds of a provider change or health status change • Must not block page load while polling or updating the health badge • Must render the Generate & Add to Pool button with enabled, loading, or disabled state based on generation lifecycle | J33: Frontend Dev | L33: 2 | M33: 0.5 | N33: =MAX(ROUND(M33*1.2/0.25,0)*0.25,0.25) -> 0.5 | O33: v0.dev — generate status badge component GitHub Copilot — polling hook | P33: React · TypeScript · Tailwind CSS · React Query | Q33: WRITE (session) | R33: Redis (session only) | S33: session.checkpoint_data [in-memory pool] | T33: Reads: session file context. Calls CLAP (Claude API). Writes generated TC list to in-memory pool. No test_case write. | U33: ENDPOINT YOU CALL: GET /api/v1/admin/llm-config (defined in FR-003 BE-06) Show provider name + status badge on Design & Author screen header. Green badge = active, amber = fallback, red = down.
A34: 3 | B34: ICE sends prompt to CLAP | C34: FR-003 | D34: Design & Author | E34: Generate & Add to Pool | F34: FE-02 | G34: Displays a generation progress indicator (spinner and status message) while the CLAP request is in flight, preventing duplicate submissions. | H34: • Displays a generation progress indicator with spinner and status message while the CLAP request is in flight. • Prevents duplicate submissions by disabling the button during active requests. • Surfaces ERR-003-* errors as user-friendly inline messages with a retry button for transient failures. | I34: • Must display a spinner and status message while the CLAP request is in flight • Must disable the Generate & Add to Pool button during active requests to prevent duplicate submissions • Must map each ERR-003-* error code to a plain-English user-friendly inline message • Must display a retry button for ERR-003-TIMEOUT and ERR-003-RATE_LIMIT errors • Must clear the error message on successful retry or new generation attempt | J34: Frontend Dev | K34: FR-003 / FE-01 | L34: 3 | M34: 1 | N34: =MAX(ROUND(M34*1.2/0.25,0)*0.25,0.25) -> 1.25 | O34: v0.dev — generate error message component GitHub Copilot — error code ↔ message mapping | P34: React · TypeScript · Tailwind CSS | Q34: WRITE (session) | R34: Redis (session only) | S34: session.checkpoint_data [in-memory pool] | T34: Reads: session file context. Calls CLAP (Claude API). Writes generated TC list to in-memory pool. No test_case write. | U34: ENDPOINT YOU CALL: GET /api/v1/admin/llm-config (defined in FR-003 BE-06) When status=down or error received from FR-004 BE-04, show user-facing error message with error code and retry suggestion.
A35: 3 | B35: ICE sends prompt to CLAP | C35: FR-003 | D35: Design & Author | E35: Generate & Add to Pool | F35: INT-01 | G35: Validates the end-to-end prompt send flow: button clicked, prompt constructed, sent to CLAP, response received, and test cases returned to FR-004. | H35: • Validates the end-to-end prompt send flow from button click through prompt construction, CLAP submission, response receipt, and test case delivery to FR-004. • Tests provider switching via the admin API to verify configuration changes take effect. • Verifies that the next generation request uses the newly configured provider. | I35: • Must validate the end-to-end flow from button click through prompt construction, CLAP submission, response receipt, and test case delivery to FR-004 • Must verify that switching the provider via admin API causes the next generation to use the new model • Must update the health badge within 30 seconds of the provider switch • Must complete provider switch without service downtime or user-visible interruption • Must confirm the new provider is used for all subsequent CLAP calls after the switch | J35: QA / Both Devs | K35: FR-003 / All BE + FE | L35: 4 | M35: 1.5 | N35: =MAX(ROUND(M35*1.2/0.25,0)*0.25,0.25) -> 1.75 | O35: Playwright AI — generate E2E switching tests Postman AI — generate admin API test collection | P35: Playwright · Postman · GitHub Actions CI | Q35: WRITE (session) | R35: Redis (session only) | S35: session.checkpoint_data [in-memory pool] | T35: Reads: session file context. Calls CLAP (Claude API). Writes generated TC list to in-memory pool. No test_case write. | U35: ENDPOINT UNDER TEST: GET/PUT /api/v1/admin/llm-config Test: switch provider → verify generation uses new provider. Test: primary down → verify fallback activates.
